Workbook

Sheet read me first!
A2: data for graphs tab
A3: Updated SAV data (preliminary and/or final) should be copied into the "data for graphs" worksheet. Add the most recent year sequentially to the right, but before the % change and restoration goal columns. You may need to insert more columns.
A4: Split segments (CB1TF, ELKOH, GUNOH, SASOH, POTTF, POTOH, PAXMH, TANMH, MANMH, BIGMH) should be summed for annual acreages. They are highlighted in "data for graphs". Make sure all the data aligns.
A5: The "year_nd" columns denote whether partial data (pd) or no data (nd) was collected. This should be updated each year. If pd or nd is present, add the corresponding year to the "No or partial data?" column.
A6: If previous year's data need to updated, please make changes in the "data for graphs" worksheet.
A8: create graphs here!
A9: Once the updated data has been entered into "data for graphs", type that year in a new column to the right row 2 in "create graphs here!"
A10: Copy the formulas from rows 3 and 4 into new column. They should reference the updated data from "data for graphs" and show the most recent acreage and restoration goal for the segment in the dropdown menu.
A11: Copy the numbers from rows 6 and 7 into the new column. They should reference the 2017 and 2025 MD restoration targets.
A12: Click in the dropdown menu to create dynamic graphs for each segment. The graphs will be displayed on the "graph" tab. The total MD SAV numbers graph will displaoy on the "Total MD SAV graph" tab when you select the last selection in the drop-down menu.
A14: graph
A15: You may need to format the x axis by right clicking on axis and select data. Make sure that the most recent year is included in the x axis range.
... A23: Export this as PDF into TEA\Common\SAVGROUP\#SAV\SAV charts by segment and save as jpeg.

Sheet data for graphs
A1: CBPSEG | B1: Segment_Name | C1: Salinity | D1: Segment + Salinity | E1: Sort | F1: 1984 | G1: _1984 | H1: 1985 | I1: _1985 | J1: 1986 | K1: _1986 | L1: 1987 | M1: _1987 | N1: 1989 | O1: _1989 | P1: 1990 | Q1: _1990 | R1: 1991 | S1: _1991 | T1: 1992 | U1: _1992 | V1: 1993 | W1: _1993 | X1: 1994 | Y1: _1994 | Z1: 1995 | AA1: _1995 | AB1: 1996 | AC1: _1996 | AD1: 1997 | AE1: _1997 | AF1: 1998 | AG1: _1998 | AH1: 1999 | AI1: _1999 | AJ1: 2000 | AK1: _2000 | AL1: 2001 | AM1: _2001 | AN1: 2002 | AO1: _2002 | AP1: 2003 | AQ1: _2003 | AR1: 2004 | AS1: _2004 | AT1: 2005 | AU1: _2005 | AV1: 2006 | AW1: _2006 | AX1: 2007 | AY1: _2007 | AZ1: 2008 | BA1: _2008 | BB1: 2009 | BC1: _2009 | BD1: 2010 | BE1: _2010 | BF1: 2011 | BG1: _2011 | BH1: 2012 | BI1: _2012 | BJ1: 2013 | BK1: _2013 | BL1: 2014 | BM1: _2014 | BN1: 2015 | BO1: _2015 | BP1: 2016 | BQ1: _2016 | BR1: 2017 | BS1: _2017 | BT1: 2018 | BU1: 2018_nd | BV1: 2019 | BW1: 2019_nd | BX1: 2020 | BY1: 2020_nd | BZ1: 2021 | CA1: 2021_nd | CB1: 2022 | CC1: 2022_nd | CD1: 2023 | CE1: 2023_nd | CF1: 2024 | CG1: 2024_nd | CH1: % change | CI1: net loss/gain | CJ1: % of goal | CK1: Restoration Acreage Goal | CL1: No or partial data?
A2: CB1TF1 | B2: Northern Chesapeake Bay Segment 1 | C2: (Tidal Fresh) | D2: =CONCATENATE(B2, " ", C2) -> Northern Chesapeake Bay Segment 1 (Tidal Fresh) | E2: 1.1 | F2: 18.03903 | H2: 42.675897 | J2: 7.981653 | L2: 8.179341 | N2: 10.551597 | P2: 29.850888 | R2: 87.526362 | T2: 72.230253 | V2: 109.27204 | X2: 297.34746 | Z2: 355.1712 | AB2: 323.12104 | AD2: 351.73637 | AF2: 359.37207 | AH2: 174.97859 | AI2: pd | AJ2: 466.84021 | AL2: 571.19476 | AN2: 639.27357 | AP2: 565.11586 | AR2: 622.91489 | AT2: 742.93621 | AV2: 606.85274 | AX2: 833.82327 | AZ2: 1007.2945 | BB2: 1078.8328 | BD2: 845.95637 | BF2: 496.9135 | BH2: 460.88486 | BJ2: 567.88349 | BL2: 529.72971 | BN2: 477.41652 | BP2: 575.93928 | BR2: 516.08923 | BT2: 523.70022 | BV2: 805.89984 | BX2: 773.2319 | BZ2: 822.30795 | CB2: 785.365 | CD2: 455.21683 | CF2: 664.19353 | CH2: =(CF2-CD2)/CD2 -> 0.45907068 | CI2: =CF2-CD2 -> 208.9767 | CJ2: =CF2/CK2 -> 0.88089328 | CK2: 754 | CL2: Partial data for 1999
A3: CB1TF2 | B3: Northern Chesapeake Bay Segment 2 | C3: (Tidal Fresh) | D3: =CONCATENATE(B3, " ", C3) -> Northern Chesapeake Bay Segment 2 (Tidal Fresh) | E3: 1.2 | F3: 5362.2623 | H3: 5038.8694 | J3: 5805.0093 | L3: 5478.3546 | N3: 4805.9683 | P3: 4381.1862 | R3: 4135.2376 | T3: 4368.46 | V3: 4322.374 | X3: 6401.4093 | Z3: 4825.8112 | AB3: 4981.7623 | AD3: 5801.2779 | AF3: 5349.0419 | AH3: 6240.936 | AI3: pd | AJ3: 7301.0379 | AL3: 7411.5949 | AN3: 8588.0115 | AP3: 7003.9129 | AR3: 9480.9929 | AT3: 8449.6299 | AV3: 8742.9742 | AX3: 11725.79 | AZ3: 14193.776 | BB3: 14182.458 | BD3: 13272.748 | BF3: 8479.3325 | BH3: 6023.924 | BJ3: 6442.4789 | BL3: 6908.2072 | BN3: 7696.4881 | BP3: 8616.7751 | BR3: 9083.7883 | BT3: 8638.2737 | BV3: 8497.2974 | BX3: 9199.8806 | BZ3: 10332.361 | CB3: 10549.447 | CD3: 10666.683 | CF3: 10925.352 | CH3: =(CF3-CD3)/CD3 -> 0.024250231 | CI3: =CF3-CD3 -> 258.66951 | CJ3: =CF3/CK3 -> 0.89927996 | CK3: 12149 | CL3: Partial data for 1999
A4: CB1TF | B4: Northern Chesapeake Bay | C4: (Tidal Fresh) | D4: =CONCATENATE(B4, " ", C4) -> Northern Chesapeake Bay (Tidal Fresh) | E4: 1 | F4: =SUM(F2:F3) -> 5380.3013 | H4: =SUM(H2:H3) -> 5081.5453 | J4: =SUM(J2:J3) -> 5812.9909 | L4: =SUM(L2:L3) -> 5486.5339 | N4: =SUM(N2:N3) -> 4816.5199 | P4: =SUM(P2:P3) -> 4411.0371 | R4: =SUM(R2:R3) -> 4222.7639 | T4: =SUM(T2:T3) -> 4440.6903 | V4: =SUM(V2:V3) -> 4431.646 | X4: =SUM(X2:X3) -> 6698.7567 | Z4: =SUM(Z2:Z3) -> 5180.9824 | AB4: =SUM(AB2:AB3) -> 5304.8833 | AD4: =SUM(AD2:AD3) -> 6153.0143 | AF4: =SUM(AF2:AF3) -> 5708.414 | AH4: =SUM(AH2:AH3) -> 6415.9146 | AI4: pd | AJ4: =SUM(AJ2:AJ3) -> 7767.8781 | AL4: =SUM(AL2:AL3) -> 7982.7897 | AN4: =SUM(AN2:AN3) -> 9227.2851 | AP4: =SUM(AP2:AP3) -> 7569.0287 | AR4: =SUM(AR2:AR3) -> 10103.908 | AT4: =SUM(AT2:AT3) -> 9192.5661 | AV4: =SUM(AV2:AV3) -> 9349.8269 | AX4: =SUM(AX2:AX3) -> 12559.613 | AZ4: =SUM(AZ2:AZ3) -> 15201.07 | BB4: =SUM(BB2:BB3) -> 15261.291 | BD4: =SUM(BD2:BD3) -> 14118.704 | BF4: =SUM(BF2:BF3) -> 8976.246 | BH4: =SUM(BH2:BH3) -> 6484.8089 | BJ4: =SUM(BJ2:BJ3) -> 7010.3624 | BL4: =SUM(BL2:BL3) -> 7437.9369 | BN4: =SUM(BN2:BN3) -> 8173.9046 | BP4: =SUM(BP2:BP3) -> 9192.7144 | BR4: =SUM(BR2:BR3) -> 9599.8775 | BT4: 9161.9739 | BV4: =SUM(BV2:BV3) -> 9303.1973 | BX4: =SUM(BX2:BX3) -> 9973.1125 | BZ4: 11154.669 | CB4: =SUM(CB2:CB3) -> 11334.812 | CD4: =SUM(CD2:CD3) -> 11121.9 | CF4: =SUM(CF2:CF3) -> 11589.546 | CH4: =(CF4-CD4)/CD4 -> 0.042047333 | CI4: =CF4-CD4 -> 467.64621 | CJ4: =CF4/CK4 -> 0.89820551 | CK4: =SUM(CK2:CK3) -> 12903 | CL4: Partial data for 1999
A5: NORTF | B5: Northeast River | C5: (Tidal Fresh) | D5: =CONCATENATE(B5, " ", C5) -> Northeast River (Tidal Fresh) | E5: 2 | F5: 0 | H5: 0 | J5: 4.966911 | L5: 0.840174 | N5: 0 | P5: 0 | R5: 0 | T5: 0 | V5: 0 | X5: 19.669956 | Z5: 16.951746 | AB5: 13.09683 | AD5: 12.306078 | AF5: 24.587445 | AH5: 14.208825 | AJ5: 23.302473 | AL5: 0 | AN5: 75.986325 | AP5: 46.036593 | AR5: 84.165666 | AT5: 78.383292 | AV5: 132.45096 | AX5: 115.05442 | AZ5: 182.71313 | BB5: 240.1415 | BD5: 228.37906 | BF5: 108.30831 | BH5: 52.288476 | BJ5: 52.041366 | BL5: 70.772304 | BN5: 83.374914 | BP5: 90.022173 | BR5: 100.35137 | BT5: 93.753534 | BV5: 86.537922 | BX5: 108.55542 | BZ5: 98.498046 | CB5: 98.868711 | CD5: 96.86516 | CF5: 146.87921 | CH5: =(CF5-CD5)/CD5 -> 0.51632653 | CI5: =CF5-CD5 -> 50.014052 | CJ5: =CF5/CK5 -> 1.6503282 | CK5: 89
A6: ELKOH1 | B6: Elk River Segment 1 | C6: (Oligohaline) | D6: =CONCATENATE(B6, " ", C6) -> Elk River Segment 1 (Oligohaline) | E6: 3.1 | F6: 33.85407 | H6: 95.260905 | J6: 13.714605 | L6: 17.890764 | N6: 467.68039 | P6: 873.97865 | R6: 663.31737 | T6: 594.59608 | V6: 233.71664 | X6: 441.51144 | Z6: 303.40166 | AB6: 107.12219 | AD6: 165.86023 | AF6: 487.67158 | AH6: 790.33191 | AJ6: 1652.8694 | AL6: 1844.948 | AN6: 374.89058 | AP6: 324.6037 | AR6: 1689.244 | AT6: 1671.6003 | AV6: 1610.3912 | AX6: 1589.5104 | AZ6: 1906.5772 | BB6: 2070.164 | BD6: 1900.7207 | BF6: 115.4745 | BH6: 114.90615 | BJ6: 113.96713 | BL6: 419.88931 | BN6: 2129.2233 | BP6: 2195.0287 | BR6: 2085.3613 | BT6: 1771.1609 | BU6: pd | BV6: 798.78307 | BX6: 612.23974 | BZ6: 115.05442 | CB6: 189.1627 | CD6: 0 | CF6: 85.597172 | CH6: 0 | CI6: =CF6-CD6 -> 85.597172 | CJ6: =CF6/CK6 -> 0.046419291 | CK6: 1844 | CL6: Partial data for 2018
A7: ELKOH2 | B7: Elk River Segment 2 | C7: (Oligohaline) | D7: =CONCATENATE(B7, " ", C7) -> Elk River Segment 2 (Oligohaline) | E7: 3.2 | F7: 0 | H7: 0 | J7: 0.469509 | L7: 0 | N7: 2.100435 | P7: 5.263443 | R7: 0.716619 | T7: 0 | V7: 0 | X7: 0 | Z7: 5.658819 | AB7: 0.914307 | AD7: 0.790752 | AF7: 21.572703 | AH7: 8.228763 | AJ7: 57.428364 | AL7: 189.75577 | AN7: 60.270129 | AP7: 21.25146 | AR7: 222.86851 | AT7: 291.91104 | AV7: 378.89376 | AX7: 390.55736 | AZ7: 440.10291 | BB7: 461.89801 | BD7: 475.29137 | BF7: 29.480223 | BH7: 0 | BJ7: 0 | BL7: 11.663592 | BN7: 121.92407 | BP7: 143.64504 | BR7: 136.52827 | BT7: 131.70963 | BV7: 21.449148 | BX7: 0 | BZ7: 0 | CB7: 0 | CD7: 0 | CF7: 0 | CH7: 0 | CI7: =CF7-CD7 -> 0 | CJ7: =CF7/CK7 -> 0 | CK7: 190
A8: ELKOH | B8: Elk River | C8: (Oligohaline) | D8: =CONCATENATE(B8, " ", C8) -> Elk River (Oligohaline) | E8: 3 | F8: =SUM(F6:F7) -> 33.85407 | H8: =SUM(H6:H7) -> 95.260905 | J8: =SUM(J6:J7) -> 14.184114 | L8: =SUM(L6:L7) -> 17.890764 | N8: =SUM(N6:N7) -> 469.78082 | P8: =SUM(P6:P7) -> 879.24209 | R8: =SUM(R6:R7) -> 664.03399 | T8: =SUM(T6:T7) -> 594.59608 | V8: =SUM(V6:V7) -> 233.71664 | X8: =SUM(X6:X7) -> 441.51144 | Z8: =SUM(Z6:Z7) -> 309.06048 | AB8: =SUM(AB6:AB7) -> 108.03649 | AD8: =SUM(AD6:AD7) -> 166.65098 | AF8: =SUM(AF6:AF7) -> 509.24429 | AH8: =SUM(AH6:AH7) -> 798.56068 | AJ8: =SUM(AJ6:AJ7) -> 1710.2977 | AL8: =SUM(AL6:AL7) -> 2034.7037 | AN8: =SUM(AN6:AN7) -> 435.16071 | AP8: =SUM(AP6:AP7) -> 345.85516 | AR8: =SUM(AR6:AR7) -> 1912.1125 | AT8: =SUM(AT6:AT7) -> 1963.5113 | AV8: =SUM(AV6:AV7) -> 1989.2849 | AX8: =SUM(AX6:AX7) -> 1980.0677 | AZ8: =SUM(AZ6:AZ7) -> 2346.6801 | BB8: =SUM(BB6:BB7) -> 2532.062 | BD8: =SUM(BD6:BD7) -> 2376.0121 | BF8: =SUM(BF6:BF7) -> 144.95473 | BH8: =SUM(BH6:BH7) -> 114.90615 | BJ8: =SUM(BJ6:BJ7) -> 113.96713 | BL8: =SUM(BL6:BL7) -> 431.5529 | BN8: =SUM(BN6:BN7) -> 2251.1474 | BP8: =SUM(BP6:BP7) -> 2338.6738 | BR8: =SUM(BR6:BR7) -> 2221.8896 | BT8: 1902.8706 | BV8: =SUM(BV6:BV7) -> 820.23222 | BX8: =SUM(BX6:BX7) -> 612.23974 | BZ8: 115.05442 | CB8: =SUM(CB6:CB7) -> 189.1627 | CD8: =SUM(CD6:CD7) -> 0 | CF8: =SUM(CF6:CF7) -> 85.597172 | CH8: 0 | CI8: =CF8-CD8 -> 85.597172 | CJ8: =CF8/CK8 -> 0.042083172 | CK8: =SUM(CK6:CK7) -> 2034 | CL8: Partial data for 2018
A9: BOHOH | B9: Bohemia River | C9: (Oligohaline) | D9: =CONCATENATE(B9, " ", C9) -> Bohemia River (Oligohaline) | E9: 4 | F9: 0 | H9: 19.348713 | J9: 3.879627 | L9: 0 | N9: 16.877613 | P9: 16.877613 | R9: 0.617775 | T9: 4.349136 | V9: 0.444798 | X9: 2.940609 | Z9: 28.219962 | AB9: 31.086438 | AD9: 37.288899 | AF9: 114.65904 | AH9: 90.44226 | AJ9: 187.11169 | AL9: 354.40516 | AN9: 136.18232 | AP9: 288.10555 | AR9: 729.76525 | AT9: 917.89009 | AV9: 708.71148 | AX9: 578.80575 | AZ9: 528.42002 | BB9: 546.90385 | BD9: 208.9315 | BF9: 53.894691 | BH9: 60.887904 | BJ9: 35.657973 | BL9: 63.26016 | BN9: 374.17396 | BP9: 295.07405 | BR9: 145.52308 | BT9: 118.41511 | BU9: pd | BV9: 83.449047 | BX9: 3.508962 | BZ9: 2.372256 | CB9: 6.350727 | CD9: 0 | CF9: 6.8942295 | CH9: 0 | CI9: =CF9-CD9 -> 6.8942295 | CJ9: =CF9/CK9 -> 0.019475225 | CK9: 354 | CL9: Partial data for 2018
A10: C&DOH | B10: Chesapeake & Delaware Canal | C10: (Oligohaline) | D10: =CONCATENATE(B10, " ", C10) -> Chesapeake & Delaware Canal (Oligohaline) | E10: 5 | F10: 0 | H10: 0 | J10: 0 | L10: 0 | N10: 0 | P10: 0 | R10: 0 | T10: 0 | V10: 0 | X10: 0 | Z10: 0 | AB10: 0 | AD10: 0 | AF10: 0 | AH10: 0 | AJ10: 0 | AL10: 6.573126 | AN10: 0 | AP10: 0 | AR10: 8.129919 | AT10: 8.698272 | AV10: 3.014742 | AX10: 2.125146 | AZ10: 12.207234 | BB10: 7.240323 | BD10: 15.740907 | BF10: 0 | BH10: 0 | BJ10: 0 | BL10: 0.568353 | BN10: 16.927035 | BP10: 21.325593 | BR10: 17.816631 | BT10: 16.531659 | BU10: pd | BV10: 0 | BX10: 1.013151 | BZ10: 0 | CB10: 0 | CD10: 0 | CF10: 0 | CH10: 0 | CI10: =CF10-CD10 -> 0 | CJ10: =CF10/CK10 -> 0 | CK10: 7 | CL10: Partial data for 2018
A11: CB2OH | B11: Upper Chesapeake Bay | C11: (Oligohaline) | D11: =CONCATENATE(B11, " ", C11) -> Upper Chesapeake Bay (Oligohaline) | E11: 6 | F11: 27.478632 | G11: pd | H11: 315.04054 | J11: 36.102771 | K11: pd | L11: 211.47674 | N11: 51.300036 | P11: 18.978048 | R11: 9.933822 | T11: 93.506424 | V11: 27.42921 | X11: 10.230354 | Z11: 23.96967 | AB11: 68.152938 | AD11: 272.24109 | AF11: 312.74242 | AH11: 1.284972 | AI11: pd | AJ11: 705.20252 | AL11: 203.12442 | AM11: pd | AN11: 502.15223 | AP11: 211.50145 | AR11: 1302.7886 | AT11: 1070.7771 | AV11: 434.71591 | AX11: 372.64188 | AZ11: 632.92284 | BB11: 745.45674 | BD11: 581.42512 | BF11: 421.22371 | BH11: 294.25859 | BJ11: 94.173621 | BL11: 302.56148 | BN11: 425.86937 | BP11: 310.39487 | BR11: 473.66045 | BT11: 631.36605 | BV11: 998.20084 | BX11: 692.45164 | BZ11: 794.95287 | CB11: 438.91678 | CD11: 243.32429 | CF11: 434.11406 | CH11: =(CF11-CD11)/CD11 -> 0.78409668 | CI11: =CF11-CD11 -> 190.78977 | CJ11: =CF11/CK11 -> 0.61576463 | CK11: 705 | CL11: Partial data for 1984, 1986, 1999, 2001
A12: SASOH1 | B12: Sassafras River Segment 1 | C12: (Oligohaline) | D12: =CONCATENATE(B12, " ", C12) -> Sassafras River Segment 1 (Oligohaline) | E12: 7.1 | F12: 49.496133 | H12: 67.95525 | J12: 75.838059 | L12: 84.486909 | N12: 222.86851 | P12: 97.138941 | R12: 74.38011 | T12: 34.545978 | V12: 186.37036 | X12: 177.22729 | Z12: 422.06388 | AB12: 233.74135 | AD12: 261.91189 | AF12: 169.51746 | AH12: 240.3639 | AJ12: 958.21845 | AL12: 1073.7177 | AN12: 709.50223 | AP12: 304.43952 | AR12: 1024.5428 | AT12: 1125.2895 | AV12: 815.2406 | AX12: 368.44101 | AZ12: 552.19201 | BB12: 807.97557 | BD12: 783.58581 | BF12: 421.81677 | BH12: 263.24628 | BJ12: 107.76467 | BL12: 110.95239 | BN12: 121.60283 | BP12: 167.86182 | BR12: 21.795102 | BT12: 133.36527 | BV12: 237.57155 | BX12: 140.80328 | BZ12: 144.43579 | CB12: 118.06916 | CD12: 6.572993 | CF12: 50.088183 | CH12: =(CF12-CD12)/CD12 -> 6.6203008 | CI12: =CF12-CD12 -> 43.515191 | CJ12: =CF12/CK12 -> 0.046680507 | CK12: 1073
A13: SASOH2 | B13: Sassafras River Segment 2 | C13: (Oligohaline) | D13: =CONCATENATE(B13, " ", C13) -> Sassafras River Segment 2 (Oligohaline) | E13: 7.2 | F13: 0 | H13: 0 | J13: 6.869658 | L13: 0 | N13: 0 | P13: 0 | R13: 0 | T13: 0 | V13: 0 | X13: 11.194083 | Z13: 22.215189 | AB13: 14.159403 | AD13: 11.86128 | AF13: 0 | AH13: 0 | AJ13: 2.026302 | AL13: 95.38446 | AN13: 120.8615 | AP13: 65.805393 | AR13: 246.51694 | AT13: 350.62438 | AV13: 49.940931 | AX13: 4.052604 | AZ13: 52.782696 | BB13: 53.178072 | BD13: 127.01454 | BF13: 93.506424 | BH13: 9.167781 | BJ13: 0 | BL13: 35.312019 | BN13: 103.41553 | BP13: 60.78906 | BR13: 19.867644 | BT13: 28.368228 | BU13: pd | BV13: 168.30662 | BX13: 28.491783 | BZ13: 59.084001 | CB13: 42.824163 | CD13: 4.0278115 | CF13: 37.362276 | CH13: =(CF13-CD13)/CD13 -> 8.2760736 | CI13: =CF13-CD13 -> 33.334464 | CJ13: =CF13/CK13 -> 0.39328712 | CK13: 95 | CL13: Partial data for 2018
A14: SASOH | B14: Sassafras River | C14: (Oligohaline) | D14: =CONCATENATE(B14, " ", C14) -> Sassafras River (Oligohaline) | E14: 7 | F14: =SUM(F12:F13) -> 49.496133 | H14: =SUM(H12:H13) -> 67.95525 | J14: =SUM(J12:J13) -> 82.707717 | L14: =SUM(L12:L13) -> 84.486909 | N14: =SUM(N12:N13) -> 222.86851 | P14: =SUM(P12:P13) -> 97.138941 | R14: =SUM(R12:R13) -> 74.38011 | T14: =SUM(T12:T13) -> 34.545978 | V14: =SUM(V12:V13) -> 186.37036 | X14: =SUM(X12:X13) -> 188.42137 | Z14: =SUM(Z12:Z13) -> 444.27907 | AB14: =SUM(AB12:AB13) -> 247.90075 | AD14: =SUM(AD12:AD13) -> 273.77317 | AF14: =SUM(AF12:AF13) -> 169.51746 | AH14: =SUM(AH12:AH13) -> 240.3639 | AJ14: =SUM(AJ12:AJ13) -> 960.24475 | AL14: =SUM(AL12:AL13) -> 1169.1021 | AN14: =SUM(AN12:AN13) -> 830.36373 | AP14: =SUM(AP12:AP13) -> 370.24491 | AR14: =SUM(AR12:AR13) -> 1271.0597 | AT14: =SUM(AT12:AT13) -> 1475.9139 | AV14: =SUM(AV12:AV13) -> 865.18153 | AX14: =SUM(AX12:AX13) -> 372.49361 | AZ14: =SUM(AZ12:AZ13) -> 604.9747 | BB14: =SUM(BB12:BB13) -> 861.15364 | BD14: =SUM(BD12:BD13) -> 910.60035 | BF14: =SUM(BF12:BF13) -> 515.32319 | BH14: =SUM(BH12:BH13) -> 272.41406 | BJ14: =SUM(BJ12:BJ13) -> 107.76467 | BL14: =SUM(BL12:BL13) -> 146.26441 | BN14: =SUM(BN12:BN13) -> 225.01837 | BP14: =SUM(BP12:BP13) -> 228.65088 | BR14: =SUM(BR12:BR13) -> 41.662746 | BT14: 161.7335 | BV14: =SUM(BV12:BV13) -> 405.87817 | BX14: =SUM(BX12:BX13) -> 169.29506 | BZ14: 203.5198 | CB14: =SUM(CB12:CB13) -> 160.89332 | CD14: =SUM(CD12:CD13) -> 10.600804 | CF14: =SUM(CF12:CF13) -> 87.450459 | CH14: =(CF14-CD14)/CD14 -> 7.2494172 | CI14: =CF14-CD14 -> 76.849655 | CJ14: =CF14/CK14 -> 0.074871969 | CK14: =SUM(CK12:CK13) -> 1168 | CL14: Partial data for 2018
A15: BSHOH | B15: Bush River | C15: (Oligohaline) | D15: =CONCATENATE(B15, " ", C15) -> Bush River (Oligohaline) | E15: 8 | F15: 5.93064 | G15: pd | H15: 29.999154 | J15: 0 | K15: pd | L15: 35.361441 | N15: 0 | P15: 0 | R15: 0 | T15: 5.732952 | V15: 0 | X15: 0 | Z15: 0 | AB15: 96.471744 | AD15: 86.364945 | AF15: 6.103617 | AH15: 0 | AI15: pd | AJ15: 194.37673 | AL15: 2.940609 | AM15: pd | AN15: 349.83363 | AP15: 390.16198 | AR15: 1024.2215 | AT15: 725.53967 | AV15: 324.03534 | AX15: 642.98022 | AZ15: 519.12869 | BB15: 381.29073 | BD15: 236.1136 | BF15: 278.49297 | BH15: 119.82364 | BJ15: 247.85133 | BL15: 222.25073 | BN15: 366.24173 | BP15: 61.629234 | BR15: 126.29792 | BT15: 431.15753 | BV15: 552.6368 | BX15: 446.18182 | BZ15: 444.3532 | CB15: 393.20143 | CD15: 290.76845 | CF15: 467.20142 | CH15: =(CF15-CD15)/CD15 -> 0.60678168 | CI15: =CF15-CD15 -> 176.43297 | CJ15: =CF15/CK15 -> 1.3348612 | CK15: 350 | CL15: Partial data for 1984, 1986, 1999, 2001
A16: GUNOH1 | B16: Gunpowder River Segment 1 | C16: (Oligohaline) | D16: =CONCATENATE(B16, " ", C16) -> Gunpowder River Segment 1 (Oligohaline) | E16: 9.1 | F16: 0 | G16: nd | H16: 78.210315 | J16: 0 | K16: nd | L16: 88.070004 | N16: 60.665505 | P16: 213.84899 | R16: 175.0033 | T16: 283.5093 | V16: 88.094715 | X16: 176.1153 | Z16: 114.36251 | AB16: 728.03548 | AD16: 1179.8761 | AF16: 1765.2303 | AH16: 160.3991 | AI16: pd | AJ16: 1861.2325 | AL16: 0 | AM16: nd | AN16: 102.69892 | AP16: 20.75724 | AR16: 1324.1884 | AT16: 442.3269 | AV16: 235.86649 | AX16: 558.93811 | AZ16: 782.74564 | BB16: 854.53109 | BD16: 857.0269 | BF16: 492.91032 | BH16: 424.68325 | BJ16: 331.76989 | BL16: 328.58217 | BN16: 344.49605 | BP16: 185.70317 | BR16: 417.98656 | BT16: 605.1971 | BV16: 978.50618 | BX16: 1023.1837 | BZ16: 933.08736 | CB16: 426.6107 | CD16: 86.560882 | CF16: 184.48859 | CH16: =(CF16-CD16)/CD16 -> 1.131316 | CI16: =CF16-CD16 -> 97.927711 | CJ16: =CF16/CK16 -> 0.099187416 | CK16: 1860 | CL16: Partial data for 1999; No data for 1984, 1986, 2001
A17: GUNOH2 | B17: Gunpowder River Segment 2 | C17: (Oligohaline) | D17: =CONCATENATE(B17, " ", C17) -> Gunpowder River Segment 2 (Oligohaline) | E17: 9.2 | F17: 0 | G17: pd | H17: 39.710577 | J17: 0 | K17: pd | L17: 0.24711 | N17: 0 | P17: 0 | R17: 26.762013 | T17: 28.046985 | V17: 27.058545 | X17: 44.430378 | Z17: 54.290067 | AB17: 190.86776 | AD17: 395.1536 | AF17: 386.40591 | AH17: 147.35169 | AI17: pd | AJ17: 571.81254 | AL17: 0 | AM17: nd | AN17: 360.38522 | AP17: 468.397 | AR17: 1066.848 | AT17: 1290.705 | AV17: 606.95158 | AX17: 905.68286 | AZ17: 936.5469 | BB17: 1033.1422 | BD17: 872.94079 | BF17: 893.15438 | BH17: 345.97871 | BJ17: 467.30972 | BL17: 587.92411 | BN17: 891.91883 | BP17: 734.5839 | BR17: 801.32831 | BT17: 908.89529 | BV17: 1060.1513 | BX17: 1114.2437 | BZ17: 1231.0032 | CB17: 859.34974 | CD17: 120.7355 | CF17: 282 | CH17: =(CF17-CD17)/CD17 -> 1.3356841 | CI17: =CF17-CD17 -> 161.2645 | CJ17: =CF17/CK17 -> 0.49300699 | CK17: 572 | CL17: Partial data for 1984, 1986, 1999; No data for 2001
A18: GUNOH | B18: Gunpowder River | C18: (Oligohaline) | D18: =CONCATENATE(B18, " ", C18) -> Gunpowder River (Oligohaline) | E18: 9 | F18: =SUM(F16:F17) -> 0 | G18: pd | H18: =SUM(H16:H17) -> 117.92089 | J18: =SUM(J16:J17) -> 0 | K18: pd | L18: =SUM(L16:L17) -> 88.317114 | N18: =SUM(N16:N17) -> 60.665505 | P18: =SUM(P16:P17) -> 213.84899 | R18: =SUM(R16:R17) -> 201.76531 | T18: =SUM(T16:T17) -> 311.55629 | V18: =SUM(V16:V17) -> 115.15326 | X18: =SUM(X16:X17) -> 220.54567 | Z18: =SUM(Z16:Z17) -> 168.65257 | AB18: =SUM(AB16:AB17) -> 918.90325 | AD18: =SUM(AD16:AD17) -> 1575.0297 | AF18: =SUM(AF16:AF17) -> 2151.6362 | AH18: =SUM(AH16:AH17) -> 307.75079 | AI18: pd | AJ18: =SUM(AJ16:AJ17) -> 2433.0451 | AL18: =SUM(AL16:AL17) -> 0 | AM18: nd | AN18: =SUM(AN16:AN17) -> 463.08414 | AP18: =SUM(AP16:AP17) -> 489.15425 | AR18: =SUM(AR16:AR17) -> 2391.0364 | AT18: =SUM(AT16:AT17) -> 1733.0319 | AV18: =SUM(AV16:AV17) -> 842.81808 | AX18: =SUM(AX16:AX17) -> 1464.621 | AZ18: =SUM(AZ16:AZ17) -> 1719.2925 | BB18: =SUM(BB16:BB17) -> 1887.6733 | BD18: =SUM(BD16:BD17) -> 1729.9677 | BF18: =SUM(BF16:BF17) -> 1386.0647 | BH18: =SUM(BH16:BH17) -> 770.66196 | BJ18: =SUM(BJ16:BJ17) -> 799.07961 | BL18: =SUM(BL16:BL17) -> 916.50628 | BN18: =SUM(BN16:BN17) -> 1236.4149 | BP18: =SUM(BP16:BP17) -> 920.28706 | BR18: =SUM(BR16:BR17) -> 1219.3149 | BT18: 1514.0924 | BV18: =SUM(BV16:BV17) -> 2038.6575 | BX18: =SUM(BX16:BX17) -> 2137.4274 | BZ18: 2164.0905 | CB18: =SUM(CB16:CB17) -> 1285.9604 | CD18: =SUM(CD16:CD17) -> 207.29638 | CF18: =SUM(CF16:CF17) -> 466.48859 | CH18: =(CF18-CD18)/CD18 -> 1.250346 | CI18: =CF18-CD18 -> 259.19221 | CJ18: =CF18/CK18 -> 0.19181274 | CK18: =SUM(CK16:CK17) -> 2432 | CL18: Partial data for 1984, 1986, 1999; No data for 2001
A19: MIDOH | B19: Middle River | C19: (Oligohaline) | D19: =CONCATENATE(B19, " ", C19) -> Middle River (Oligohaline) | E19: 10 | F19: 0 | G19: nd | H19: 193.61068 | J19: 0 | K19: nd | L19: 94.025355 | N19: 19.571112 | P19: 7.388589 | R19: 19.472268 | T19: 112.97869 | V19: 16.482237 | X19: 61.826922 | Z19: 11.762436 | AB19: 76.999476 | AD19: 290.03301 | AF19: 105.5901 | AH19: 95.13735 | AJ19: 740.26743 | AL19: 0 | AM19: nd | AN19: 629.4633 | AP19: 391.07629 | AR19: 670.70596 | AT19: 453.76809 | AV19: 230.67718 | AX19: 550.3881 | AZ19: 826.68179 | BB19: 780.34867 | BD19: 658.27633 | BF19: 311.82811 | BH19: 309.13461 | BJ19: 366.63711 | BL19: 519.07927 | BN19: 841.18715 | BP19: 950.2615 | BR19: 857.00219 | BT19: 864.39078 | BV19: 458.83385 | BX19: 503.73373 | BZ19: 687.97895 | CB19: 416.99812 | CD19: 277.99313 | CF19: 410.58967 | CH19: =(CF19-CD19)/CD19 -> 0.47697778 | CI19: =CF19-CD19 -> 132.59654 | CJ19: =CF19/CK19 -> 0.46710997 | CK19: 879 | CL19: Partial data for 2018; No data for 1984, 1986, 2001
A20: BACOH | B20: Back River | C20: (Oligohaline) | D20: =CONCATENATE(B20, " ", C20) -> Back River (Oligohaline) | E20: 11 | F20: 0 | H20: 0 | J20: 0 | L20: 0 | N20: 0 | P20: 0 | R20: 0 | T20: 0 | V20: 0 | X20: 0 | Z20: 0 | AB20: 0 | AD20: 0 | AF20: 0 | AH20: 0 | AJ20: 0 | AL20: 0 | AN20: 0 | AP20: 0 | AR20: 30.048576 | AT20: 0 | AV20: 0 | AX20: 0 | AZ20: 0 | BB20: 0 | BD20: 0.024711 | BF20: 10.576308 | BH20: 0.024711 | BJ20: 0 | BL20: 0 | BN20: 0 | BP20: 0 | BR20: 0 | BT20: 0.568353 | BV20: 14.974866 | BX20: 1.23555 | BZ20: 26.144238 | CB20: 23.796693 | CD20: 6.1034935 | CF20: 82.508359 | CH20: =(CF20-CD20)/CD20 -> 12.518219 | CI20: =CF20-CD20 -> 76.404866 | CJ20: =CF20/CK20 -> 2.7502786 | CK20: 30
A21: CB3MH | B21: Upper Central Chesapeake Bay | C21: (Mesohaline) | D21: =CONCATENATE(B21, " ", C21) -> Upper Central Chesapeake Bay (Mesohaline) | E21: 12 | F21: 944.55326 | H21: 905.46046 | J21: 435.136 | L21: 561.75516 | N21: 227.88484 | P21: 86.191968 | R21: 54.883131 | T21: 435.90204 | V21: 800.21631 | X21: 819.91098 | Z21: 854.7782 | AB21: 900.74066 | AD21: 916.35801 | AF21: 761.79071 | AH21: 6.869658 | AI21: pd | AJ21: 9.241914 | AL21: 1.23555 | AM21: pd | AN21: 94.692552 | AP21: 22.808253 | AQ21: pd | AR21: 908.62347 | AT21: 566.47496 | AV21: 169.44333 | AX21: 123.50558 | AZ21: 188.74262 | BB21: 234.45797 | BD21: 202.58078 | BF21: 767.44953 | BH21: 433.72747 | BJ21: 124.09864 | BL21: 363.44939 | BN21: 630.62472 | BP21: 744.96252 | BR21: 272.09282 | BT21: 466.3707 | BV21: 785.11789 | BX21: 340.7894 | BZ21: 372.9137 | CB21: 651.62907 | CD21: 339.47285 | CF21: 575.13689 | CH21: =(CF21-CD21)/CD21 -> 0.69420585 | CI21: =CF21-CD21 -> 235.66404 | CJ21: =CF21/CK21 -> 0.41980795 | CK21: 1370 | CL21: Partial data for 1999, 2001, 2003
A22: PATMH | B22: Patapsco River | C22: (Mesohaline) | D22: =CONCATENATE(B22, " ", C22) -> Patapsco River (Mesohaline) | E22: 13 | F22: 0 | H22: 0 | J22: 0 | L22: 0 | N22: 0 | P22: 0 | R22: 0 | T22: 0 | V22: 0 | X22: 0.914307 | Z22: 0 | AB22: 5.68353 | AD22: 4.769223 | AF22: 14.480646 | AH22: 0 | AI22: pd | AJ22: 0 | AL22: 0 | AM22: pd | AN22: 7.882809 | AP22: 6.523704 | AR22: 202.35838 | AT22: 278.86363 | AV22: 48.087606 | AX22: 9.068937 | AZ22: 18.137874 | BB22: 11.540037 | BD22: 0 | BF22: 3.632517 | BH22: 0 | BJ22: 0 | BL22: 16.778769 | BN22: 39.611733 | BP22: 3.45954 | BR22: 14.282958 | BT22: 30.567507 | BV22: 140.77857 | BX22: 143.47207 | BZ22: 164.37757 | CB22: 176.8072 | CD22: 179.69476 | CF22: 228.22618 | CH22: =(CF22-CD22)/CD22 -> 0.27007701 | CI22: =CF22-CD22 -> 48.531422 | CJ22: =CF22/CK22 -> 0.58669969 | CK22: 389 | CL22: Partial data for 1999, 2001
A23: MAGMH | B23: Magothy River | C23: (Mesohaline) | D23: =CONCATENATE(B23, " ", C23) -> Magothy River (Mesohaline) | E23: 14 | F23: 23.524872 | H23: 12.528477 | J23: 9.686712 | L23: 0.642486 | N23: 0 | P23: 0 | R23: 0 | T23: 0 | V23: 32.643231 | X23: 45.814194 | Z23: 78.259737 | AB23: 91.801365 | AD23: 132.15443 | AF23: 197.73742 | AH23: 65.23704 | AI23: pd | AJ23: 89.898618 | AL23: 0 | AM23: nd | AN23: 208.78324 | AP23: 168.72671 | AR23: 299.52203 | AT23: 308.29444 | AV23: 250.2483 | AX23: 82.930116 | AZ23: 89.651508 | BB23: 12.10839 | BD23: 1.754481 | BF23: 7.858098 | BH23: 0 | BJ23: 0 | BL23: 18.953337 | BN23: 31.704213 | BP23: 11.292927 | BR23: 23.376606 | BT23: 35.756817 | BV23: 183.42975 | BX23: 123.08549 | BZ23: 60.393684 | CB23: 80.953236 | CD23: 72.797133 | CF23: 72.846554 | CH23: =(CF23-CD23)/CD23 -> 0.00067888663 | CI23: =CF23-CD23 -> 0.049421 | CJ23: =CF23/CK23 -> 0.12581443 | CK23: 579 | CL23: Partial data for 1999, No data for 2001
A24: CHSMH | B24: Lower Chester River | C24: (Mesohaline) | D24: =CONCATENATE(B24, " ", C24) -> Lower Chester River (Mesohaline) | E24: 15 | F24: 1033.2658 | H24: 910.60035 | J24: 399.45331 | L24: 708.48908 | N24: 186.37036 | P24: 80.187195 | R24: 85.178817 | T24: 194.59912 | V24: 757.51571 | X24: 1012.7309 | Z24: 1097.6626 | AB24: 770.48898 | AD24: 1049.748 | AF24: 1180.914 | AH24: 735.74531 | AJ24: 0 | AL24: 205.5461 | AN24: 204.85419 | AP24: 116.93245 | AQ24: pd | AR24: 730.70427 | AT24: 461.84859 | AV24: 183.89926 | AX24: 67.559874 | AZ24: 82.78185 | BB24: 95.335038 | BD24: 84.116244 | BF24: 283.48459 | BH24: 173.81717 | BJ24: 36.720546 | BL24: 143.62033 | BN24: 382.72397 | BP24: 545.86599 | BR24: 235.14988 | BT24: 381.76024 | BV24: 766.53522 | BX24: 369.80012 | BZ24: 265.34672 | CB24: 362.85632 | CD24: 271.17303 | CF24: 320.89055 | CH24: =(CF24-CD24)/CD24 -> 0.18334245 | CI24: =CF24-CD24 -> 49.717526 | CJ24: =CF24/CK24 -> 0.10959377 | CK24: 2928
A25: CHSOH | B25: Middle Chester River | C25: (Oligohaline) | D25: =CONCATENATE(B25, " ", C25) -> Middle Chester River (Oligohaline) | E25: 16 | F25: 0 | H25: 0 | J25: 0 | L25: 0 | N25: 0 | P25: 0 | R25: 0 | T25: 0 | V25: 0 | X25: 0 | Z25: 0 | AB25: 0 | AD25: 0 | AF25: 0 | AH25: 0 | AJ25: 0 | AL25: 0 | AN25: 0 | AP25: 0 | AR25: 4.349136 | AT25: 228.08253 | AV25: 0 | AX25: 0 | AZ25: 0 | BB25: 0 | BD25: 0 | BF25: 17.940186 | BH25: 0 | BJ25: 0 | BL25: 19.669956 | BN25: 93.580557 | BP25: 101.78461 | BR25: 69.264933 | BT25: 217.03671 | BV25: 366.29115 | BX25: 228.84857 | BZ25: 9.760845 | CB25: 0 | CD25: 0 | CF25: 0 | CH25: 0 | CI25: =CF25-CD25 -> 0 | CJ25: =CF25/CK25 -> 0 | CK25: 77
A26: CHSTF | B26: Upper Chester River | C26: (Tidal Fresh) | D26: =CONCATENATE(B26, " ", C26) -> Upper Chester River (Tidal Fresh) | E26: 17 | F26: 0 | H26: 0 | J26: 0 | L26: 0 | N26: 0 | P26: 0 | R26: 0 | T26: 0 | V26: 0 | X26: 0 | Z26: 0 | AB26: 0 | AD26: 0 | AF26: 0 | AH26: 0 | AJ26: 0 | AL26: 0 | AN26: 0 | AP26: 0 | AR26: 0 | AT26: 0.963729 | AV26: 0 | AX26: 0 | AZ26: 0 | BB26: 0 | BD26: 0 | BF26: 0 | BH26: 0 | BJ26: 0 | BL26: 9.909111 | BN26: 14.505357 | BP26: 358.33421 | BR26: 409.95549 | BT26: 472.30134 | BV26: 483.27303 | BX26: 191.23843 | BZ26: 14.554779 | CB26: 5.065755 | CD26: 4.3243375 | CF26: 2.7428655 | CH26: =(CF26-CD26)/CD26 -> -0.36571429 | CI26: =CF26-CD26 -> -1.581472 | CJ26: =CF26/CK26 -> 2.7428655 | CK26: 1
A27: CB4MH | B27: Middle Central Chesapeake Bay | C27: (Mesohaline) | D27: =CONCATENATE(B27, " ", C27) -> Middle Central Chesapeake Bay (Mesohaline) | E27: 18 | F27: 45.048153 | H27: 87.575784 | J27: 30.913461 | L27: 15.691485 | N27: 5.980062 | P27: 12.133101 | R27: 5.584686 | T27: 18.088452 | V27: 12.058968 | X27: 0 | Z27: 0 | AB27: 0 | AD27: 50.113908 | AF27: 0 | AH27: 24.21678 | AJ27: 0 | AL27: 112.16323 | AM27: pd | AN27: 269.44874 | AP27: 21.375015 | AR27: 10.403331 | AT27: 0 | AV27: 0 | AX27: 0 | AZ27: 0 | BB27: 0.370665 | BD27: 0 | BF27: 68.177649 | BH27: 0 | BJ27: 0 | BL27: 0 | BN27: 0 | BP27: 35.732106 | BR27: 48.828936 | BT27: 22.882386 | BU27: pd | BV27: 161.75821 | BX27: 44.751621 | BZ27: 42.379365 | CB27: 38.277339 | CD27: 43.589322 | CF27: 14.3568 | CH27: =(CF27-CD27)/CD27 -> -0.67063492 | CI27: =CF27-CD27 -> -29.232522 | CJ27: =CF27/CK27 -> 0.0056679039 | CK27: 2533 | CL27: Partial data for 2001, 2018
A28: EASMH | B28: Eastern Bay | C28: (Mesohaline) | D28: =CONCATENATE(B28, " ", C28) -> Eastern Bay (Mesohaline) | E28: 19 | F28: 215.23281 | H28: 971.98247 | J28: 624.32341 | L28: 2216.9721 | N28: 2051.2601 | P28: 961.60385 | R28: 167.86182 | T28: 1370.3238 | V28: 1813.0955 | X28: 2412.1396 | Z28: 3328.6953 | AB28: 3678.2571 | AD28: 4567.3836 | AF28: 2736.1255 | AH28: 4955.6428 | AJ28: 0 | AL28: 2886.8132 | AN28: 2779.6168 | AP28: 1637.9439 | AR28: 1039.1964 | AT28: 767.52366 | AV28: 565.33826 | AX28: 80.113062 | AZ28: 89.873907 | BB28: 473.24036 | BD28: 421.69322 | BF28: 1633.0017 | BH28: 228.55204 | BJ28: 48.482982 | BL28: 216.19654 | BN28: 1505.2459 | BP28: 2327.0596 | BR28: 2441.2738 | BT28: 1837.0652 | BV28: 2003.7903 | BX28: 841.38484 | BZ28: 511.19646 | CB28: 572.13378 | CD28: 974.85394 | CF28: 623.91541 | CH28: =(CF28-CD28)/CD28 -> -0.35999087 | CI28: =CF28-CD28 -> -350.93852 | CJ28: =CF28/CK28 -> 0.10048565 | CK28: 6209
A29: CHOMH1 | B29: Mouth of the Choptank River | C29: (Mesohaline) | D29: =CONCATENATE(B29, " ", C29) -> Mouth of the Choptank River (Mesohaline) | E29: 20 | F29: 142.70602 | H29: 3471.5001 | J29: 700.33445 | L29: 697.0726 | N29: 2070.9795 | P29: 294.57983 | R29: 201.76532 | T29: 2302.4721 | V29: 4284.8133 | X29: 3607.4106 | Z29: 3656.5855 | AB29: 5791.3935 | AD29: 6900.7691 | AF29: 5642.2873 | AH29: 3789.5801 | AJ29: 1681.9542 | AL29: 5259.7611 | AN29: 6584.5425 | AP29: 2970.2622 | AR29: 3772.4307 | AT29: 2292.4395 | AV29: 1042.8783 | AX29: 1256.9003 | AZ29: 460.5142 | BB29: 649.03441 | BD29: 404.12369 | BF29: 2825.9005 | BH29: 755.95891 | BJ29: 1261.7684 | BL29: 3792.5454 | BN29: 6045.6203 | BP29: 7260.759 | BR29: 8707.6128 | BT29: 5350.0056 | BU29: pd | BV29: 5317.4365 | BX29: 4531.5279 | BZ29: 4170.1789 | CB29: 5001.9759 | CD29: 5424.7208 | CF29: 3214.2924 | CH29: =(CF29-CD29)/CD29 -> -0.4074732 | CI29: =CF29-CD29 -> -2210.4284 | CJ29: =CF29/CK29 -> 0.39275323 | CK29: 8184 | CL29: Partial data for 2018
A30: CHOMH2 | B30: Lower Choptank River | C30: (Mesohaline) | D30: =CONCATENATE(B30, " ", C30) -> Lower Choptank River (Mesohaline) | E30: 21 | F30: 0 | H30: 89.997462 | J30: 21.720969 | L30: 0 | N30: 0 | P30: 0 | R30: 0 | T30: 13.986426 | V30: 9.933822 | X30: 0 | Z30: 0 | AB30: 0 | AD30: 4.349136 | AF30: 0 | AH30: 0 | AJ30: 0 | AL30: 148.14245 | AN30: 154.44375 | AP30: 0 | AR30: 0.98844 | AT30: 0 | AV30: 0 | AX30: 0 | AZ30: 0 | BB30: 0 | BD30: 0 | BF30: 44.72691 | BH30: 18.162585 | BJ30: 0 | BL30: 19.842933 | BN30: 32.989185 | BP30: 30.023865 | BR30: 20.880795 | BT30: 0 | BU30: pd | BV30: 23.055363 | BX30: 30.518085 | BZ30: 9.118359 | CB30: 7.487433 | CD30: 15.518194 | CF30: 9.834779 | CH30: =(CF30-CD30)/CD30 -> -0.36624204 | CI30: =CF30-CD30 -> -5.683415 | CJ30: =CF30/CK30 -> 0.0060671061 | CK30: 1621 | CL30: Partial data for 2018
A31: CHOOH | B31: Middle Choptank River | C31: (Oligohaline) | D31: =CONCATENATE(B31, " ", C31) -> Middle Choptank River (Oligohaline) | E31: 22 | F31: 0 | H31: 0 | J31: 0 | L31: 0 | N31: 0 | P31: 0 | R31: 0 | T31: 0 | V31: 0 | X31: 0 | Z31: 0 | AB31: 0 | AD31: 0 | AF31: 0 | AH31: 0 | AJ31: 0 | AL31: 0 | AN31: 0 | AP31: 0 | AR31: 0 | AT31: 0 | AV31: 0 | AX31: 0 | AZ31: 0 | BB31: 0 | BD31: 0 | BF31: 0 | BH31: 0 | BJ31: 0 | BL31: 0 | BN31: 19.200447 | BP31: 26.514903 | BR31: 0 | BT31: 0 | BV31: 7.363878 | BX31: 0 | BZ31: 0 | CB31: 1.359105 | CD31: 0 | CF31: 0 | CH31: 0 | CI31: =CF31-CD31 -> 0 | CJ31: =CF31/CK31 -> 0 | CK31: 72
A32: CHOTF | B32: Upper Choptank River | C32: (Tidal Fresh) | D32: =CONCATENATE(B32, " ", C32) -> Upper Choptank River (Tidal Fresh) | E32: 23 | F32: 0 | H32: 0 | J32: 0 | L32: 0 | N32: 0 | P32: 0 | R32: 0 | T32: 0 | V32: 0 | X32: 0 | Z32: 0 | AB32: 0 | AD32: 0 | AF32: 0 | AH32: 0 | AJ32: 0 | AL32: 0 | AN32: 0 | AP32: 0 | AR32: 0 | AT32: 0 | AV32: 0 | AX32: 0 | AZ32: 0 | BB32: 0 | BD32: 0 | BF32: 0 | BH32: 0 | BJ32: 0 | BL32: 0 | BN32: 0 | BP32: 0 | BR32: 0 | BT32: 0 | BV32: 0 | BX32: 0 | BZ32: 0 | CB32: 0 | CD32: 0 | CF32: 0 | CH32: 0 | CI32: =CF32-CD32 -> 0 | CK32: NGZ
A33: LCHMH | B33: Little Choptank River | C33: (Mesohaline) | D33: =CONCATENATE(B33, " ", C33) -> Little Choptank River (Mesohaline) | E33: 24 | F33: 69.487332 | H33: 907.5609 | J33: 400.49118 | L33: 175.27512 | N33: 68.573025 | P33: 168.94911 | R33: 74.157711 | T33: 344.86672 | V33: 381.56255 | X33: 132.89576 | Z33: 45.344685 | AB33: 850.55262 | AD33: 1308.1756 | AF33: 1525.2123 | AH33: 1603.3238 | AJ33: 1157.488 | AL33: 2378.2608 | AN33: 2904.9263 | AP33: 783.90705 | AR33: 1220.4763 | AT33: 259.4655 | AV33: 120.81208 | AX33: 141.14923 | AZ33: 80.459016 | BB33: 176.60952 | BD33: 170.85185 | BF33: 476.62577 | BH33: 114.31309 | BJ33: 49.347867 | BL33: 240.98167 | BN33: 847.83441 | BP33: 1836.6698 | BR33: 2448.3906 | BT33: 1081.9217 | BU33: pd | BV33: 1503.096 | BX33: 551.2777 | BZ33: 176.23885 | CB33: 377.36168 | CD33: 902.57572 | CF33: 156.56573 | CH33: =(CF33-CD33)/CD33 -> -0.82653452 | CI33: =CF33-CD33 -> -746.00999 | CJ33: =CF33/CK33 -> 0.038411611 | CK33: 4076 | CL33: Partial data for 2018
A34: SEVMH | B34: Severn River | C34: (Mesohaline) | D34: =CONCATENATE(B34, " ", C34) -> Severn River (Mesohaline) | E34: 25 | F34: 0 | H34: 0 | J34: 0.296532 | L34: 0 | N34: 0 | P34: 0 | R34: 0 | T34: 0 | V34: 0 | X34: 77.394852 | Z34: 125.95197 | AB34: 272.46349 | AD34: 306.09516 | AF34: 403.77774 | AH34: 454.95422 | AI34: pd | AJ34: 128.12653 | AL34: 119.89777 | AM34: pd | AN34: 282.02664 | AP34: 221.58354 | AR34: 388.03683 | AT34: 425.52342 | AV34: 410.8698 | AX34: 325.93809 | AZ34: 311.23505 | BB34: 211.00723 | BD34: 174.7809 | BF34: 192.17745 | BH34: 180.78568 | BJ34: 74.997885 | BL34: 143.44735 | BN34: 231.34438 | BP34: 310.98793 | BR34: 194.82152 | BT34: 223.65926 | BV34: 404.09898 | BX34: 294.85165 | BZ34: 226.40218 | CB34: 270.36305 | CD34: 325.90678 | CF34: 330.20641 | CH34: =(CF34-CD34)/CD34 -> 0.013192812 | CI34: =CF34-CD34 -> 4.299627 | CJ34: =CF34/CK34 -> 0.72572838 | CK34: 455 | CL34: Partial data for 1999, 2001
A35: SOUMH | B35: South River | C35: (Mesohaline) | D35: =CONCATENATE(B35, " ", C35) -> South River (Mesohaline) | E35: 26 | F35: 0 | H35: 0 | J35: 0 | L35: 0 | N35: 0 | P35: 0 | R35: 0 | T35: 0 | V35: 0 | X35: 4.176159 | Z35: 4.522113 | AB35: 21.523281 | AD35: 40.402485 | AF35: 54.3642 | AH35: 17.198856 | AJ35: 0 | AL35: 26.539614 | AM35: pd | AN35: 35.608551 | AP35: 13.615761 | AR35: 46.086015 | AT35: 10.180932 | AV35: 0 | AX35: 8.006364 | AZ35: 0 | BB35: 0 | BD35: 0 | BF35: 0 | BH35: 4.20087 | BJ35: 0 | BL35: 6.153039 | BN35: 9.933822 | BP35: 14.851311 | BR35: 0 | BT35: 0 | BV35: 18.014319 | BX35: 4.250292 | BZ35: 0 | CB35: 0.370665 | CD35: 1.284946 | CF35: 0.296526 | CH35: =(CF35-CD35)/CD35 -> -0.76923077 | CI35: =CF35-CD35 -> -0.98842 | CJ35: =CF35/CK35 -> 0.00061905219 | CK35: 479 | CL35: Partial data for 2001
A36: RHDMH | B36: Rhode River | C36: (Mesohaline) | D36: =CONCATENATE(B36, " ", C36) -> Rhode River (Mesohaline) | E36: 27 | F36: 0 | H36: 0 | J36: 0 | L36: 0 | N36: 0 | P36: 0 | R36: 0 | T36: 0 | V36: 0 | X36: 0 | Z36: 0 | AB36: 0 | AD36: 0 | AF36: 0 | AH36: 0 | AJ36: 0 | AL36: 0 | AN36: 0 | AP36: 0 | AR36: 0 | AT36: 0 | AV36: 0 | AX36: 0 | AZ36: 0 | BB36: 0 | BD36: 0 | BF36: 0 | BH36: 0 | BJ36: 0 | BL36: 0 | BN36: 0 | BP36: 0 | BR36: 0 | BT36: 0.963729 | BV36: 2.4711 | BX36: 0 | BZ36: 0 | CB36: 0 | CD36: 0 | CF36: 0 | CH36: 0 | CI36: =CF36-CD36 -> 0 | CJ36: =CF36/CK36 -> 0 | CK36: 60
A37: WSTMH | B37: West River | C37: (Mesohaline) | D37: =CONCATENATE(B37, " ", C37) -> West River (Mesohaline) | E37: 28 | F37: 0 | H37: 5.411709 | J37: 1.013151 | L37: 0 | N37: 0 | P37: 0 | R37: 0 | T37: 0 | V37: 0 | X37: 11.564748 | Z37: 0 | AB37: 0 | AD37: 0 | AF37: 7.932231 | AH37: 0 | AJ37: 0 | AL37: 0 | AN37: 0 | AP37: 23.030652 | AR37: 0 | AT37: 0 | AV37: 0 | AX37: 0 | AZ37: 0 | BB37: 0 | BD37: 0 | BF37: 0 | BH37: 0 | BJ37: 0 | BL37: 0 | BN37: 0 | BP37: 7.536855 | BR37: 0 | BT37: 0 | BV37: 0 | BX37: 0 | BZ37: 0 | CB37: 0 | CD37: 0 | CF37: 0 | CH37: 0 | CI37: =CF37-CD37 -> 0 | CJ37: =CF37/CK37 -> 0 | CK37: 238
A38: CB5MH | B38: Lower Central Chesapeake Bay | C38: (Mesohaline) | D38: =CONCATENATE(B38, " ", C38) -> Lower Central Chesapeake Bay (Mesohaline) | E38: 29 | F38: 13.368651 | G38: pd | H38: 934.12522 | J38: 600.50201 | L38: 1324.4849 | N38: 1352.2353 | P38: 1632.7793 | R38: 580.31312 | T38: 2195.2758 | V38: 1132.3816 | X38: 25.773573 | Z38: 0 | AB38: 3.780783 | AD38: 170.38234 | AF38: 4.991622 | AH38: 656.84309 | AJ38: 1377.7124 | AL38: 2156.7019 | AN38: 2136.9331 | AP38: 699.27188 | AR38: 397.35288 | AT38: 919.12564 | AV38: 573.19636 | AX38: 503.98084 | AZ38: 1133.9878 | BB38: 2280.0345 | BD38: 432.07183 | BF38: 701.29818 | BH38: 525.70181 | BJ38: 807.70375 | BL38: 2082.0747 | BN38: 2135.0551 | BP38: 2806.8484 | BR38: 3045.8779 | BT38: 2668.9857 | BV38: 901.87737 | BX38: 829.44943 | BZ38: 1209.4305 | CB38: 1346.4283 | CD38: 1405.1626 | CF38: 1326.3361 | CH38: =(CF38-CD38)/CD38 -> -0.056097775 | CI38: =CF38-CD38 -> -78.826495 | CJ38: =CF38/CK38 -> 0.16037921 | CK38: 8270 | CL38: Partial data for 1984
A39: HNGMH | B39: Honga River | C39: (Mesohaline) | D39: =CONCATENATE(B39, " ", C39) -> Honga River (Mesohaline) | E39: 30 | F39: 33.162162 | H39: 783.85763 | J39: 636.01172 | L39: 1585.8531 | N39: 2466.6026 | P39: 2885.9977 | R39: 3329.6837 | T39: 3792.0265 | V39: 4560.2668 | X39: 3438.3627 | Z39: 2213.2901 | AB39: 1539.4953 | AD39: 2200.5393 | AF39: 781.78191 | AH39: 1913.8422 | AJ39: 2824.9368 | AL39: 4949.2426 | AN39: 6322.853 | AP39: 2842.6299 | AR39: 3431.0235 | AT39: 4376.3181 | AV39: 2094.7268 | AX39: 1992.7445 | AZ39: 3964.6823 | BB39: 4922.1347 | BD39: 2174.8151 | BF39: 2592.5299 | BH39: 2403.8614 | BJ39: 2953.6811 | BL39: 5214.4411 | BN39: 6216.8675 | BP39: 7857.0107 | BR39: 7665.5993 | BT39: 6240.7383 | BU39: pd | BV39: 2567.9918 | BX39: 2335.3872 | BZ39: 2800.3247 | CB39: 3039.4036 | CD39: 3976.7596 | CF39: 4355.6704 | CH39: =(CF39-CD39)/CD39 -> 0.095281295 | CI39: =CF39-CD39 -> 378.91081 | CJ39: =CF39/CK39 -> 0.56122541 | CK39: 7761 | CL39: Partial data for 2018
A40: FSBMH | B40: Fishing Bay | C40: (Mesohaline) | D40: =CONCATENATE(B40, " ", C40) -> Fishing Bay (Mesohaline) | E40: 31 | F40: 0 | H40: 0 | J40: 0.197688 | L40: 5.041044 | N40: 21.869235 | P40: 13.368651 | R40: 1.48266 | T40: 33.656382 | V40: 38.722137 | X40: 63.952068 | Z40: 26.762013 | AB40: 0 | AD40: 0 | AF40: 0 | AH40: 4.991622 | AJ40: 6.326016 | AL40: 5.535264 | AN40: 108.80253 | AP40: 15.07371 | AR40: 16.704636 | AT40: 6.597837 | AV40: 12.997986 | AX40: 0 | AZ40: 22.165767 | BB40: 147.20343 | BD40: 138.48044 | BF40: 156.44534 | BH40: 64.619265 | BJ40: 122.71483 | BL40: 191.04074 | BN40: 284.1765 | BP40: 311.1362 | BR40: 366.34058 | BT40: 218.49466 | BV40: 12.701454 | BX40: 71.958432 | BZ40: 156.64303 | CB40: 103.02016 | CD40: 271.17303 | CF40: 45.714425 | CH40: =(CF40-CD40)/CD40 -> -0.83141972 | CI40: =CF40-CD40 -> -225.4586 | CJ40: =CF40/CK40 -> 0.23205292 | CK40: 197
...

Sheet create graphs here!
A1: 17 | B1: ="Data for " & A3 -> Data for GUNOH | AQ1: copy formulas over
A2: CBPSEG | B2: Segment_Name | C2: 1984 | D2: 1985 | E2: 1986 | F2: 1987 | G2: 1989 | H2: 1990 | I2: 1991 | J2: 1992 | K2: 1993 | L2: 1994 | M2: 1995 | N2: 1996 | O2: 1997 | P2: 1998 | Q2: 1999 | R2: 2000 | S2: 2001 | T2: 2002 | U2: 2003 | V2: 2004 | W2: 2005 | X2: 2006 | Y2: 2007 | Z2: 2008 | AA2: 2009 | AB2: 2010 | AC2: 2011 | AD2: 2012 | AE2: 2013 | AF2: 2014 | AG2: 2015 | AH2: 2016 | AI2: 2017 | AJ2: 2018 | AK2: 2019 | AL2: 2020 | AM2: 2021 | AN2: 2022 | AO2: 2023 | AP2: 2024
A3: =INDEX('data for graphs'!A2:A76,$A$1) -> GUNOH | B3: =INDEX('data for graphs'!D2:D76,$A$1) -> Gunpowder River (Oligohaline) | C3: =INDEX('data for graphs'!F2:F76,$A$1) -> 0 | D3: =INDEX('data for graphs'!H2:H76,$A$1) -> 117.92089 | E3: =INDEX('data for graphs'!J2:J76,$A$1) -> 0 | F3: =INDEX('data for graphs'!L2:L76,$A$1) -> 88.317114 | G3: =INDEX('data for graphs'!N2:N76,$A$1) -> 60.665505 | H3: =INDEX('data for graphs'!P2:P76,$A$1) -> 213.84899 | I3: =INDEX('data for graphs'!R2:R76,$A$1) -> 201.76531 | J3: =INDEX('data for graphs'!T2:T76,$A$1) -> 311.55629 | K3: =INDEX('data for graphs'!V2:V76,$A$1) -> 115.15326 | L3: =INDEX('data for graphs'!X2:X76,$A$1) -> 220.54567 | M3: =INDEX('data for graphs'!Z2:Z76,$A$1) -> 168.65257 | N3: =INDEX('data for graphs'!AB2:AB76,$A$1) -> 918.90325 | O3: =INDEX('data for graphs'!AD2:AD76,$A$1) -> 1575.0297 | P3: =INDEX('data for graphs'!AF2:AF76,$A$1) -> 2151.6362 | Q3: =INDEX('data for graphs'!AH2:AH76,$A$1) -> 307.75079 | R3: =INDEX('data for graphs'!AJ2:AJ76,$A$1) -> 2433.0451 | S3: =INDEX('data for graphs'!AL2:AL76,$A$1) -> 0 | T3: =INDEX('data for graphs'!AN2:AN76,$A$1) -> 463.08414 | U3: =INDEX('data for graphs'!AP2:AP76,$A$1) -> 489.15425 | V3: =INDEX('data for graphs'!AR2:AR76,$A$1) -> 2391.0364 | W3: =INDEX('data for graphs'!AT2:AT76,$A$1) -> 1733.0319 | X3: =INDEX('data for graphs'!AV2:AV76,$A$1) -> 842.81808 | Y3: =INDEX('data for graphs'!AX2:AX76,$A$1) -> 1464.621 | Z3: =INDEX('data for graphs'!AZ2:AZ76,$A$1) -> 1719.2925 | AA3: =INDEX('data for graphs'!BB2:BB76,$A$1) -> 1887.6733 | AB3: =INDEX('data for graphs'!BD2:BD76,$A$1) -> 1729.9677 | AC3: =INDEX('data for graphs'!BF2:BF76,$A$1) -> 1386.0647 | AD3: =INDEX('data for graphs'!BH2:BH76,$A$1) -> 770.66196 | AE3: =INDEX('data for graphs'!BJ2:BJ76,$A$1) -> 799.07961 | AF3: =INDEX('data for graphs'!BL2:BL76,$A$1) -> 916.50628 | AG3: =INDEX('data for graphs'!BN2:BN76,$A$1) -> 1236.4149 | AH3: =INDEX('data for graphs'!BP2:BP76,$A$1) -> 920.28706 | AI3: =INDEX('data for graphs'!BR2:BR76,$A$1) -> 1219.3149 | AJ3: =INDEX('data for graphs'!BT2:BT76,$A$1) -> 1514.0924 | AK3: =INDEX('data for graphs'!BV2:BV76,$A$1) -> 2038.6575 | AL3: =INDEX('data for graphs'!BX2:BX76,$A$1) -> 2137.4274 | AM3: =INDEX('data for graphs'!BZ2:BZ76,$A$1) -> 2164.0905 | AN3: =INDEX('data for graphs'!CB2:CB76,$A$1) -> 1285.9604 | AO3: =INDEX('data for graphs'!CD2:CD76,$A$1) -> 207.29638 | AP3: =INDEX('data for graphs'!CF2:CF76,$A$1) -> 466.48859
A4: =INDEX('data for graphs'!A2:A76,$A$1) -> GUNOH | B4: Restoration Goal | C4: =INDEX('data for graphs'!$CK$2:$CK$76,$A$1) -> 2432 | D4: =INDEX('data for graphs'!$CK$2:$CK$76,$A$1) -> 2432 | E4: =INDEX('data for graphs'!$CK$2:$CK$76,$A$1) -> 2432 | F4: =INDEX('data for graphs'!$CK$2:$CK$76,$A$1) -> 2432 | G4: =INDEX('data for graphs'!$CK$2:$CK$76,$A$1) -> 2432 | H4: =INDEX('data for graphs'!$CK$2:$CK$76,$A$1) -> 2432 | I4: =INDEX('data for graphs'!$CK$2:$CK$76,$A$1) -> 2432 | J4: =INDEX('data for graphs'!$CK$2:$CK$76,$A$1) -> 2432 | ... AP4: =INDEX('data for graphs'!$CK$2:$CK$76,$A$1) -> 2432
A5: =INDEX('data for graphs'!A2:A76,$A$1) -> GUNOH | B5: =INDEX('data for graphs'!CL2:CL76&" ",$A$1) -> Partial data for 1984, 1986, 1999; No data for 2001
A6: =INDEX('data for graphs'!A3:A77,$A$1) -> MIDOH | B6: 2017 Target | C6: 57000 | D6: 57000 | E6: 57000 | F6: 57000 | G6: 57000 | H6: 57000 | I6: 57000 | J6: 57000 | K6: 57000 | L6: 57000 | M6: 57000 | N6: 57000 | O6: 57000 | P6: 57000 | Q6: 57000 | R6: 57000 | S6: 57000 | T6: 57000 | U6: 57000 | V6: 57000 | W6: 57000 | X6: 57000 | Y6: 57000 | Z6: 57000 | AA6: 57000 | AB6: 57000 | AC6: 57000 | AD6: 57000 | AE6: 57000 | AF6: 57000 | AG6: 57000 | AH6: 57000 | AI6: 57000 | AJ6: 57000 | AK6: 57000 | AL6: 57000 | AM6: 57000 | AN6: 57000 | AO6: 57000 | AP6: 57000
A7: =INDEX('data for graphs'!A4:A78,$A$1) -> BACOH | B7: 2025 Target | C7: 79800 | D7: 79800 | E7: 79800 | F7: 79800 | G7: 79800 | H7: 79800 | I7: 79800 | J7: 79800 | K7: 79800 | L7: 79800 | M7: 79800 | N7: 79800 | O7: 79800 | P7: 79800 | Q7: 79800 | R7: 79800 | S7: 79800 | T7: 79800 | U7: 79800 | V7: 79800 | W7: 79800 | X7: 79800 | Y7: 79800 | Z7: 79800 | AA7: 79800 | AB7: 79800 | AC7: 79800 | AD7: 79800 | AE7: 79800 | AF7: 79800 | AG7: 79800 | AH7: 79800 | AI7: 79800 | AJ7: 79800 | AK7: 79800 | AL7: 79800 | AM7: 79800 | AN7: 79800 | AO7: 79800 | AP7: 79800
B11: select a segment from the drop down above to create a graph in the graph tab
B12: make sure data from most recent year has been copied to this sheet
B13: may need to change decimal places from 0 to 2 on some graph y axis
B14: may need to format x axis to update new years on graph tab
